Workbook

Sheet CBA2
A1: PT POS INDONESIA (PERSERO) | AF1: Lampiran 2
A2: KCU BATAM 29400
A4: COST AND BENEFIT ANALYSIS
A5: CB2940026023 Pengiriman Barang Pindah Tujuan Tangerang
A6: BATAM 29400
A8: NO | B8: KAB / KOTA | C8: ALOKASI | E8: PENDAPATAN | L8: BIAYA LANGSUNG | Y8: JUMLAH BIAYA LANGSUNG (PROYEK) | Z8: BIAYA TIDAK LANGSUNG | AD8: JUMLAH BIAYA TIDAK LANGSUNG | AE8: TOTAL BIAYA PROYEK | AF8: LABA | AG8: %
E9: TARIF POS (Rp) | F9: ONGKOS KIRIM | G9: TOTAL NILAI PPN | H9: Packing | I9: PPN Barang | J9: Nilai Packing | K9: TOTAL NILAI PROJECT | L9: Biaya Pickup | M9: RITASE | N9: TARIF/RITASE | O9: DPP | P9: PPN | Q9: PPH | R9: JUMLAH YANG HARUS DIBAYARKAN | S9: JUMLAH SEWA TOTAL KBM | T9: =RBL!D24 -> Perjalanan Dinas Dalam Negeri | U9: Biaya Pemasaran | V9: TOTAL BIAYA OPERASI | W9: ATK | X9: UMUM | Z9: Overhead | AA9: COF | AB9: ASURANSI TIDAK LANGSUNG | AC9: RESIKO LAINNYA
C10: Berat (Kg) | D10: Koli
L11: KBM
G12: 0.011 | I12: 0.11 | L12: 0 | Z12: 0.01 | AA12: =(30/365)*8% -> 0.0065753425 | AB12: 0.0024
A13: 1 | B13: 2 | C13: 3 | D13: 4 | E13: 5 | F13: 6 | G13: 7 | H13: 8 | I13: 9 | J13: 10 | K13: 11 | L13: 12 | M13: 13 | N13: 14 | O13: 15 | P13: 16 | Q13: 17 | R13: 18 | S13: 19 | T13: 20 | U13: 21 | V13: 17 | W13: 18 | X13: 19 | Y13: 20 | Z13: 21 | AA13: 22 | AB13: 23 | AC13: 24 | AD13: 25 | AE13: 26 | AF13: 27 | AG13: 28
A14: 1 | B14: Tangerang | C14: 2587 | D14: 122 | F14: 33000000 | I14: =(H14*100/111)*$I$12 -> 0 | J14: =H14-I14 -> 0 | K14: =F14 -> 33000000 | L14: =C14*$L$12 -> 0 | N14: 28600000 | Q14: =N14*2/100 -> 572000 | R14: =N14-Q14 -> 28028000 | S14: =N14 -> 28600000 | T14: =$T$12*D14 -> 0 | U14: =$U$12*D14 -> 0 | V14: =S14 -> 28600000 | X14: =(D14/D$36)*'RBL 2'!F$37 -> 0 | Y14: =SUM(V14:X14) -> 28600000 | Z14: =Y14*$Z$12 -> 286000 | AA14: =Y14*$AA$12 -> 188054.79 | AC14: =Y14*$AC$12 -> 0 | AD14: =SUM(Z14:AC14) -> 474054.79 | AE14: =Y14+AD14 -> 29074055 | AF14: =(F14+J14)-AE14 -> 3925945.2 | AG14: =AF14/(F14) -> 0.11896804
G15: =F15*$G$12 -> 0 | I15: =(H15*100/111)*$I$12 -> 0 | J15: =H15-I15 -> 0 | K15: =F15+G15+H15 -> 0 | L15: =C15*$L$12 -> 0 | M15: 1 | O15: =N15/1.011 -> 0 | P15: =O15*1.1% -> 0 | Q15: =N15*2/100 -> 0 | R15: =(O15+P15)-Q15 -> 0 | S15: =N15+Q15 -> 0 | T15: =$T$12*D15 -> 0 | U15: =$U$12*D15 -> 0 | V15: =L15+S15+T15+U15 -> 0 | W15: =(D15/D$36)*'RBL 2'!F$25 -> 0 | X15: =(D15/D$36)*'RBL 2'!F$37 -> 0 | Y15: =SUM(V15:X15) -> 0 | Z15: =Y15*$Z$12 -> 0 | AA15: =Y15*$AA$12 -> 0 | AB15: =C15*$AB$13 -> 0 | AC15: =Y15*$AC$12 -> 0 | AD15: =SUM(Z15:AC15) -> 0 | AE15: =Y15+AD15 -> 0 | AF15: =(F15+J15)-AE15 -> 0 | AG15: =AF15/(F15) -> #DIV/0!
A16: 9 | G16: =F16*$G$12 -> 0 | I16: =(H16*100/111)*$I$12 -> 0 | J16: =H16-I16 -> 0 | K16: =F16+G16+H16 -> 0 | L16: =C16*$L$12 -> 0 | M16: 1 | O16: =N16/1.011 -> 0 | P16: =O16*1.1% -> 0 | Q16: =N16*2/100 -> 0 | R16: =(O16+P16)-Q16 -> 0 | S16: =N16+Q16 -> 0 | T16: =$T$12*D16 -> 0 | U16: =$U$12*D16 -> 0 | V16: =L16+S16+T16+U16 -> 0 | W16: =(D16/D$36)*'RBL 2'!F$25 -> 0 | X16: =(D16/D$36)*'RBL 2'!F$37 -> 0 | Y16: =SUM(V16:X16) -> 0 | Z16: =Y16*$Z$12 -> 0 | AA16: =Y16*$AA$12 -> 0 | AB16: =C16*$AB$13 -> 0 | AC16: =Y16*$AC$12 -> 0 | AD16: =SUM(Z16:AC16) -> 0 | AE16: =Y16+AD16 -> 0 | AF16: =(F16+J16)-AE16 -> 0 | AG16: =AF16/(F16) -> #DIV/0!
A17: 10 | G17: =F17*$G$12 -> 0 | I17: =(H17*100/111)*$I$12 -> 0 | J17: =H17-I17 -> 0 | K17: =F17+G17+H17 -> 0 | L17: =C17*$L$12 -> 0 | M17: 1 | O17: =N17/1.011 -> 0 | P17: =O17*1.1% -> 0 | Q17: =N17*2/100 -> 0 | R17: =(O17+P17)-Q17 -> 0 | S17: =N17+Q17 -> 0 | T17: =$T$12*D17 -> 0 | U17: =$U$12*D17 -> 0 | V17: =L17+S17+T17+U17 -> 0 | W17: =(D17/D$36)*'RBL 2'!F$25 -> 0 | X17: =(D17/D$36)*'RBL 2'!F$37 -> 0 | Y17: =SUM(V17:X17) -> 0 | Z17: =Y17*$Z$12 -> 0 | AA17: =Y17*$AA$12 -> 0 | AB17: =C17*$AB$13 -> 0 | AC17: =Y17*$AC$12 -> 0 | AD17: =SUM(Z17:AC17) -> 0 | AE17: =Y17+AD17 -> 0 | AF17: =(F17+J17)-AE17 -> 0 | AG17: =AF17/(F17) -> #DIV/0!
A18: 11 | G18: =F18*$G$12 -> 0 | I18: =(H18*100/111)*$I$12 -> 0 | J18: =H18-I18 -> 0 | K18: =F18+G18+H18 -> 0 | L18: =C18*$L$12 -> 0 | M18: 1 | O18: =N18/1.011 -> 0 | P18: =O18*1.1% -> 0 | Q18: =N18*2/100 -> 0 | R18: =(O18+P18)-Q18 -> 0 | S18: =N18+Q18 -> 0 | T18: =$T$12*D18 -> 0 | U18: =$U$12*D18 -> 0 | V18: =L18+S18+T18+U18 -> 0 | W18: =(D18/D$36)*'RBL 2'!F$25 -> 0 | X18: =(D18/D$36)*'RBL 2'!F$37 -> 0 | Y18: =SUM(V18:X18) -> 0 | Z18: =Y18*$Z$12 -> 0 | AA18: =Y18*$AA$12 -> 0 | AB18: =C18*$AB$13 -> 0 | AC18: =Y18*$AC$12 -> 0 | AD18: =SUM(Z18:AC18) -> 0 | AE18: =Y18+AD18 -> 0 | AF18: =(F18+J18)-AE18 -> 0 | AG18: =AF18/(F18) -> #DIV/0!
A19: 12 | G19: =F19*$G$12 -> 0 | I19: =(H19*100/111)*$I$12 -> 0 | J19: =H19-I19 -> 0 | K19: =F19+G19+H19 -> 0 | L19: =C19*$L$12 -> 0 | M19: 1 | O19: =N19/1.011 -> 0 | P19: =O19*1.1% -> 0 | Q19: =N19*2/100 -> 0 | R19: =(O19+P19)-Q19 -> 0 | S19: =N19+Q19 -> 0 | T19: =$T$12*D19 -> 0 | U19: =$U$12*D19 -> 0 | V19: =L19+S19+T19+U19 -> 0 | W19: =(D19/D$36)*'RBL 2'!F$25 -> 0 | X19: =(D19/D$36)*'RBL 2'!F$37 -> 0 | Y19: =SUM(V19:X19) -> 0 | Z19: =Y19*$Z$12 -> 0 | AA19: =Y19*$AA$12 -> 0 | AB19: =C19*$AB$13 -> 0 | AC19: =Y19*$AC$12 -> 0 | AD19: =SUM(Z19:AC19) -> 0 | AE19: =Y19+AD19 -> 0 | AF19: =(F19+J19)-AE19 -> 0 | AG19: =AF19/(F19) -> #DIV/0!
A20: 13 | G20: =F20*$G$12 -> 0 | I20: =(H20*100/111)*$I$12 -> 0 | J20: =H20-I20 -> 0 | K20: =F20+G20+H20 -> 0 | L20: =C20*$L$12 -> 0 | M20: 1 | O20: =N20/1.011 -> 0 | P20: =O20*1.1% -> 0 | Q20: =N20*2/100 -> 0 | R20: =(O20+P20)-Q20 -> 0 | S20: =N20+Q20 -> 0 | T20: =$T$12*D20 -> 0 | U20: =$U$12*D20 -> 0 | V20: =L20+S20+T20+U20 -> 0 | W20: =(D20/D$36)*'RBL 2'!F$25 -> 0 | X20: =(D20/D$36)*'RBL 2'!F$37 -> 0 | Y20: =SUM(V20:X20) -> 0 | Z20: =Y20*$Z$12 -> 0 | AA20: =Y20*$AA$12 -> 0 | AB20: =C20*$AB$13 -> 0 | AC20: =Y20*$AC$12 -> 0 | AD20: =SUM(Z20:AC20) -> 0 | AE20: =Y20+AD20 -> 0 | AF20: =(F20+J20)-AE20 -> 0 | AG20: =AF20/(F20) -> #DIV/0!
A21: 14 | G21: =F21*$G$12 -> 0 | I21: =(H21*100/111)*$I$12 -> 0 | J21: =H21-I21 -> 0 | K21: =F21+G21+H21 -> 0 | L21: =C21*$L$12 -> 0 | M21: 1 | O21: =N21/1.011 -> 0 | P21: =O21*1.1% -> 0 | Q21: =N21*2/100 -> 0 | R21: =(O21+P21)-Q21 -> 0 | S21: =N21+Q21 -> 0 | T21: =$T$12*D21 -> 0 | U21: =$U$12*D21 -> 0 | V21: =L21+S21+T21+U21 -> 0 | W21: =(D21/D$36)*'RBL 2'!F$25 -> 0 | X21: =(D21/D$36)*'RBL 2'!F$37 -> 0 | Y21: =SUM(V21:X21) -> 0 | Z21: =Y21*$Z$12 -> 0 | AA21: =Y21*$AA$12 -> 0 | AB21: =C21*$AB$13 -> 0 | AC21: =Y21*$AC$12 -> 0 | AD21: =SUM(Z21:AC21) -> 0 | AE21: =Y21+AD21 -> 0 | AF21: =(F21+J21)-AE21 -> 0 | AG21: =AF21/(F21) -> #DIV/0!
A22: 15 | G22: =F22*$G$12 -> 0 | I22: =(H22*100/111)*$I$12 -> 0 | J22: =H22-I22 -> 0 | K22: =F22+G22+H22 -> 0 | L22: =C22*$L$12 -> 0 | M22: 1 | O22: =N22/1.011 -> 0 | P22: =O22*1.1% -> 0 | Q22: =N22*2/100 -> 0 | R22: =(O22+P22)-Q22 -> 0 | S22: =N22+Q22 -> 0 | T22: =$T$12*D22 -> 0 | U22: =$U$12*D22 -> 0 | V22: =L22+S22+T22+U22 -> 0 | W22: =(D22/D$36)*'RBL 2'!F$25 -> 0 | X22: =(D22/D$36)*'RBL 2'!F$37 -> 0 | Y22: =SUM(V22:X22) -> 0 | Z22: =Y22*$Z$12 -> 0 | AA22: =Y22*$AA$12 -> 0 | AB22: =C22*$AB$13 -> 0 | AC22: =Y22*$AC$12 -> 0 | AD22: =SUM(Z22:AC22) -> 0 | AE22: =Y22+AD22 -> 0 | AF22: =(F22+J22)-AE22 -> 0 | AG22: =AF22/(F22) -> #DIV/0!
A23: 16 | G23: =F23*$G$12 -> 0 | I23: =(H23*100/111)*$I$12 -> 0 | J23: =H23-I23 -> 0 | K23: =F23+G23+H23 -> 0 | L23: =C23*$L$12 -> 0 | M23: 1 | O23: =N23/1.011 -> 0 | P23: =O23*1.1% -> 0 | Q23: =N23*2/100 -> 0 | R23: =(O23+P23)-Q23 -> 0 | S23: =N23+Q23 -> 0 | T23: =$T$12*D23 -> 0 | U23: =$U$12*D23 -> 0 | V23: =L23+S23+T23+U23 -> 0 | W23: =(D23/D$36)*'RBL 2'!F$25 -> 0 | X23: =(D23/D$36)*'RBL 2'!F$37 -> 0 | Y23: =SUM(V23:X23) -> 0 | Z23: =Y23*$Z$12 -> 0 | AA23: =Y23*$AA$12 -> 0 | AB23: =C23*$AB$13 -> 0 | AC23: =Y23*$AC$12 -> 0 | AD23: =SUM(Z23:AC23) -> 0 | AE23: =Y23+AD23 -> 0 | AF23: =(F23+J23)-AE23 -> 0 | AG23: =AF23/(F23) -> #DIV/0!
A24: 17 | G24: =F24*$G$12 -> 0 | I24: =(H24*100/111)*$I$12 -> 0 | J24: =H24-I24 -> 0 | K24: =F24+G24+H24 -> 0 | L24: =C24*$L$12 -> 0 | M24: 1 | O24: =N24/1.011 -> 0 | P24: =O24*1.1% -> 0 | Q24: =N24*2/100 -> 0 | R24: =(O24+P24)-Q24 -> 0 | S24: =N24+Q24 -> 0 | T24: =$T$12*D24 -> 0 | U24: =$U$12*D24 -> 0 | V24: =L24+S24+T24+U24 -> 0 | W24: =(D24/D$36)*'RBL 2'!F$25 -> 0 | X24: =(D24/D$36)*'RBL 2'!F$37 -> 0 | Y24: =SUM(V24:X24) -> 0 | Z24: =Y24*$Z$12 -> 0 | AA24: =Y24*$AA$12 -> 0 | AB24: =C24*$AB$13 -> 0 | AC24: =Y24*$AC$12 -> 0 | AD24: =SUM(Z24:AC24) -> 0 | AE24: =Y24+AD24 -> 0 | AF24: =(F24+J24)-AE24 -> 0 | AG24: =AF24/(F24) -> #DIV/0!
A25: 18 | G25: =F25*$G$12 -> 0 | I25: =(H25*100/111)*$I$12 -> 0 | J25: =H25-I25 -> 0 | K25: =F25+G25+H25 -> 0 | L25: =C25*$L$12 -> 0 | M25: 1 | O25: =N25/1.011 -> 0 | P25: =O25*1.1% -> 0 | Q25: =N25*2/100 -> 0 | R25: =(O25+P25)-Q25 -> 0 | S25: =N25+Q25 -> 0 | T25: =$T$12*D25 -> 0 | U25: =$U$12*D25 -> 0 | V25: =L25+S25+T25+U25 -> 0 | W25: =(D25/D$36)*'RBL 2'!F$25 -> 0 | X25: =(D25/D$36)*'RBL 2'!F$37 -> 0 | Y25: =SUM(V25:X25) -> 0 | Z25: =Y25*$Z$12 -> 0 | AA25: =Y25*$AA$12 -> 0 | AB25: =C25*$AB$13 -> 0 | AC25: =Y25*$AC$12 -> 0 | AD25: =SUM(Z25:AC25) -> 0 | AE25: =Y25+AD25 -> 0 | AF25: =(F25+J25)-AE25 -> 0 | AG25: =AF25/(F25) -> #DIV/0!
A26: 19 | F26: =C26*E26 -> 0 | G26: =F26*$G$12 -> 0 | I26: =(H26*100/111)*$I$12 -> 0 | J26: =H26-I26 -> 0 | K26: =F26+G26+H26 -> 0 | L26: =C26*$L$12 -> 0 | M26: 1 | O26: =N26/1.011 -> 0 | P26: =O26*1.1% -> 0 | Q26: =N26*2/100 -> 0 | R26: =(O26+P26)-Q26 -> 0 | S26: =N26+Q26 -> 0 | T26: =$T$12*D26 -> 0 | U26: =$U$12*D26 -> 0 | V26: =L26+S26+T26+U26 -> 0 | W26: =(D26/D$36)*'RBL 2'!F$25 -> 0 | X26: =(D26/D$36)*'RBL 2'!F$37 -> 0 | Y26: =SUM(V26:X26) -> 0 | Z26: =Y26*$Z$12 -> 0 | AA26: =Y26*$AA$12 -> 0 | AB26: =C26*$AB$13 -> 0 | AC26: =Y26*$AC$12 -> 0 | AD26: =SUM(Z26:AC26) -> 0 | AE26: =Y26+AD26 -> 0 | AF26: =(F26+J26)-AE26 -> 0 | AG26: =AF26/(F26) -> #DIV/0!
A27: 20 | F27: =C27*E27 -> 0 | G27: =F27*$G$12 -> 0 | I27: =(H27*100/111)*$I$12 -> 0 | J27: =H27-I27 -> 0 | K27: =F27+G27+H27 -> 0 | L27: =C27*$L$12 -> 0 | M27: 1 | O27: =N27/1.011 -> 0 | P27: =O27*1.1% -> 0 | Q27: =N27*2/100 -> 0 | R27: =(O27+P27)-Q27 -> 0 | S27: =N27+Q27 -> 0 | T27: =$T$12*D27 -> 0 | U27: =$U$12*D27 -> 0 | V27: =L27+S27+T27+U27 -> 0 | W27: =(D27/D$36)*'RBL 2'!F$25 -> 0 | X27: =(D27/D$36)*'RBL 2'!F$37 -> 0 | Y27: =SUM(V27:X27) -> 0 | Z27: =Y27*$Z$12 -> 0 | AA27: =Y27*$AA$12 -> 0 | AB27: =C27*$AB$13 -> 0 | AC27: =Y27*$AC$12 -> 0 | AD27: =SUM(Z27:AC27) -> 0 | AE27: =Y27+AD27 -> 0 | AF27: =(F27+J27)-AE27 -> 0 | AG27: =AF27/(F27) -> #DIV/0!
A28: 21 | F28: =C28*E28 -> 0 | G28: =F28*$G$12 -> 0 | I28: =(H28*100/111)*$I$12 -> 0 | J28: =H28-I28 -> 0 | K28: =F28+G28+H28 -> 0 | L28: =C28*$L$12 -> 0 | M28: 1 | O28: =N28/1.011 -> 0 | P28: =O28*1.1% -> 0 | Q28: =N28*2/100 -> 0 | R28: =(O28+P28)-Q28 -> 0 | S28: =N28+Q28 -> 0 | T28: =$T$12*D28 -> 0 | U28: =$U$12*D28 -> 0 | V28: =L28+S28+T28+U28 -> 0 | W28: =(D28/D$36)*'RBL 2'!F$25 -> 0 | X28: =(D28/D$36)*'RBL 2'!F$37 -> 0 | Y28: =SUM(V28:X28) -> 0 | Z28: =Y28*$Z$12 -> 0 | AA28: =Y28*$AA$12 -> 0 | AB28: =C28*$AB$13 -> 0 | AC28: =Y28*$AC$12 -> 0 | AD28: =SUM(Z28:AC28) -> 0 | AE28: =Y28+AD28 -> 0 | AF28: =(F28+J28)-AE28 -> 0 | AG28: =AF28/(F28) -> #DIV/0!
A29: 22 | F29: =C29*E29 -> 0 | G29: =F29*$G$12 -> 0 | I29: =(H29*100/111)*$I$12 -> 0 | J29: =H29-I29 -> 0 | K29: =F29+G29+H29 -> 0 | L29: =C29*$L$12 -> 0 | M29: 1 | O29: =N29/1.011 -> 0 | P29: =O29*1.1% -> 0 | Q29: =N29*2/100 -> 0 | R29: =(O29+P29)-Q29 -> 0 | S29: =N29+Q29 -> 0 | T29: =$T$12*D29 -> 0 | U29: =$U$12*D29 -> 0 | V29: =L29+S29+T29+U29 -> 0 | W29: =(D29/D$36)*'RBL 2'!F$25 -> 0 | X29: =(D29/D$36)*'RBL 2'!F$37 -> 0 | Y29: =SUM(V29:X29) -> 0 | Z29: =Y29*$Z$12 -> 0 | AA29: =Y29*$AA$12 -> 0 | AB29: =C29*$AB$13 -> 0 | AC29: =Y29*$AC$12 -> 0 | AD29: =SUM(Z29:AC29) -> 0 | AE29: =Y29+AD29 -> 0 | AF29: =(F29+J29)-AE29 -> 0 | AG29: =AF29/(F29) -> #DIV/0!
A30: 23 | F30: =C30*E30 -> 0 | G30: =F30*$G$12 -> 0 | I30: =(H30*100/111)*$I$12 -> 0 | J30: =H30-I30 -> 0 | K30: =F30+G30+H30 -> 0 | L30: =C30*$L$12 -> 0 | M30: 1 | O30: =N30/1.011 -> 0 | P30: =O30*1.1% -> 0 | Q30: =N30*2/100 -> 0 | R30: =(O30+P30)-Q30 -> 0 | S30: =N30+Q30 -> 0 | T30: =$T$12*D30 -> 0 | U30: =$U$12*D30 -> 0 | V30: =L30+S30+T30+U30 -> 0 | W30: =(D30/D$36)*'RBL 2'!F$25 -> 0 | X30: =(D30/D$36)*'RBL 2'!F$37 -> 0 | Y30: =SUM(V30:X30) -> 0 | Z30: =Y30*$Z$12 -> 0 | AA30: =Y30*$AA$12 -> 0 | AB30: =C30*$AB$13 -> 0 | AC30: =Y30*$AC$12 -> 0 | AD30: =SUM(Z30:AC30) -> 0 | AE30: =Y30+AD30 -> 0 | AF30: =(F30+J30)-AE30 -> 0 | AG30: =AF30/(F30) -> #DIV/0!
A31: 24 | F31: =C31*E31 -> 0 | G31: =F31*$G$12 -> 0 | I31: =(H31*100/111)*$I$12 -> 0 | J31: =H31-I31 -> 0 | K31: =F31+G31+H31 -> 0 | L31: =C31*$L$12 -> 0 | M31: 1 | O31: =N31/1.011 -> 0 | P31: =O31*1.1% -> 0 | Q31: =N31*2/100 -> 0 | R31: =(O31+P31)-Q31 -> 0 | S31: =N31+Q31 -> 0 | T31: =$T$12*D31 -> 0 | U31: =$U$12*D31 -> 0 | V31: =L31+S31+T31+U31 -> 0 | W31: =(D31/D$36)*'RBL 2'!F$25 -> 0 | X31: =(D31/D$36)*'RBL 2'!F$37 -> 0 | Y31: =SUM(V31:X31) -> 0 | Z31: =Y31*$Z$12 -> 0 | AA31: =Y31*$AA$12 -> 0 | AB31: =C31*$AB$13 -> 0 | AC31: =Y31*$AC$12 -> 0 | AD31: =SUM(Z31:AC31) -> 0 | AE31: =Y31+AD31 -> 0 | AF31: =(F31+J31)-AE31 -> 0 | AG31: =AF31/(F31) -> #DIV/0!
A32: 25 | F32: =C32*E32 -> 0 | G32: =F32*$G$12 -> 0 | I32: =(H32*100/111)*$I$12 -> 0 | J32: =H32-I32 -> 0 | K32: =F32+G32+H32 -> 0 | L32: =C32*$L$12 -> 0 | M32: 1 | O32: =N32/1.011 -> 0 | P32: =O32*1.1% -> 0 | Q32: =N32*2/100 -> 0 | R32: =(O32+P32)-Q32 -> 0 | S32: =N32+Q32 -> 0 | T32: =$T$12*D32 -> 0 | U32: =$U$12*D32 -> 0 | V32: =L32+S32+T32+U32 -> 0 | W32: =(D32/D$36)*'RBL 2'!F$25 -> 0 | X32: =(D32/D$36)*'RBL 2'!F$37 -> 0 | Y32: =SUM(V32:X32) -> 0 | Z32: =Y32*$Z$12 -> 0 | AA32: =Y32*$AA$12 -> 0 | AB32: =C32*$AB$13 -> 0 | AC32: =Y32*$AC$12 -> 0 | AD32: =SUM(Z32:AC32) -> 0 | AE32: =Y32+AD32 -> 0 | AF32: =(F32+J32)-AE32 -> 0 | AG32: =AF32/(F32) -> #DIV/0!
A33: 26 | F33: =C33*E33 -> 0 | G33: =F33*$G$12 -> 0 | I33: =(H33*100/111)*$I$12 -> 0 | J33: =H33-I33 -> 0 | K33: =F33+G33+H33 -> 0 | L33: =C33*$L$12 -> 0 | M33: 1 | O33: =N33/1.011 -> 0 | P33: =O33*1.1% -> 0 | Q33: =N33*2/100 -> 0 | R33: =(O33+P33)-Q33 -> 0 | S33: =N33+Q33 -> 0 | T33: =$T$12*D33 -> 0 | U33: =$U$12*D33 -> 0 | V33: =L33+S33+T33+U33 -> 0 | W33: =(D33/D$36)*'RBL 2'!F$25 -> 0 | X33: =(D33/D$36)*'RBL 2'!F$37 -> 0 | Y33: =SUM(V33:X33) -> 0 | Z33: =Y33*$Z$12 -> 0 | AA33: =Y33*$AA$12 -> 0 | AB33: =C33*$AB$13 -> 0 | AC33: =Y33*$AC$12 -> 0 | AD33: =SUM(Z33:AC33) -> 0 | AE33: =Y33+AD33 -> 0 | AF33: =(F33+J33)-AE33 -> 0 | AG33: =AF33/(F33) -> #DIV/0!
A34: 27 | F34: =C34*E34 -> 0 | G34: =F34*$G$12 -> 0 | I34: =(H34*100/111)*$I$12 -> 0 | J34: =H34-I34 -> 0 | K34: =F34+G34+H34 -> 0 | L34: =C34*$L$12 -> 0 | M34: 1 | O34: =N34/1.011 -> 0 | P34: =O34*1.1% -> 0 | Q34: =N34*2/100 -> 0 | R34: =(O34+P34)-Q34 -> 0 | S34: =N34+Q34 -> 0 | T34: =$T$12*D34 -> 0 | U34: =$U$12*D34 -> 0 | V34: =L34+S34+T34+U34 -> 0 | W34: =(D34/D$36)*'RBL 2'!F$25 -> 0 | X34: =(D34/D$36)*'RBL 2'!F$37 -> 0 | Y34: =SUM(V34:X34) -> 0 | Z34: =Y34*$Z$12 -> 0 | AA34: =Y34*$AA$12 -> 0 | AB34: =C34*$AB$13 -> 0 | AC34: =Y34*$AC$12 -> 0 | AD34: =SUM(Z34:AC34) -> 0 | AE34: =Y34+AD34 -> 0 | AF34: =(F34+J34)-AE34 -> 0 | AG34: =AF34/(F34) -> #DIV/0!
A36: JUMLAH | C36: =SUM(C14:C35) -> 2587 | D36: =SUM(D14:D35) -> 122 | F36: =SUM(F14:F35) -> 33000000 | G36: =SUM(G14:G35) -> 0 | H36: =SUM(H14:H35) -> 0 | I36: =SUM(I14:I35) -> 0 | J36: =SUM(J14:J35) -> 0 | K36: =SUM(K14:K35) -> 33000000 | L36: =SUM(L14:L35) -> 0 | N36: =SUM(N14:N35) -> 28600000 | O36: =SUM(O14:O35) -> 0 | P36: =SUM(P14:P35) -> 0 | Q36: =SUM(Q14:Q35) -> 572000 | R36: =SUM(R14:R35) -> 28028000 | S36: =SUM(S14:S35) -> 28600000 | T36: =SUM(T14:T35) -> 0 | U36: =SUM(U14:U35) -> 0 | ... AF36: =SUM(AF14:AF35) -> 3925945.2 | AG36: =AF36/(F36) -> 0.11896804
U38: =U37:U38 -> 0 | AC38: ='rekap CBA 1'!G59 -> Batam, 17 September 2026
B39: Mengetahuai : | F39: Ditetapkan Oleh | K39: Mengetahui | V39: Mengetahui | Z39: Diperiksa Oleh : | AE39: Dibuat Oleh
B40: EGM KCU BATAM | F40: EVP Regional I | K40: Deputi EVP | V40: Deputi OVP | Z40: Manajer Penjualan | AE40: AM Penjualan
B44: Khresna Adi Nugraha | E44: Raden Bagus Muhammad Yusuf | Z44: Ikhsan Radiansyah | AE44: Riky Juliadi
B45: Nippos : 986393010 | F45: Nippos : 973343140 | Z45: Nippos : 995480412 | AE45: Nippos : 989453856

Sheet Packing List
A1: No | B1: Uraian Barang | C1: Jumlah Satuan | D1: Jenis Satuan | E1: No | F1: Armada | G1: Nama Barang | H1: Qty | I1: P (cm) | J1: L (cm) | K1: T (cm) | L1: Berat/Unit (kg) | M1: Total Berat (kg) | N1: Volume/Unit (m³) | O1: Total Volume (m³)
A2: 1 | B2: MEJA TAMU | C2: 1 | D2: PCE - Piece | E2: 1 | F2: CDD Box 1 | G2: Kardus pakaian besar | H2: 12 | I2: 60 | J2: 50 | K2: 50 | L2: 15 | M2: =H2*L2 -> 180 | N2: =I2*J2*K2/1000000 -> 0.15 | O2: =H2*N2 -> 1.8
A3: 2 | B3: KURSI TAMU | C3: 4 | D3: PCE - Piece | E3: 2 | F3: CDD Box 1 | G3: Kardus buku/arsip | H3: 10 | I3: 50 | J3: 40 | K3: 40 | L3: 22 | M3: =H3*L3 -> 220 | N3: =I3*J3*K3/1000000 -> 0.08 | O3: =H3*N3 -> 0.8
A4: 3 | B4: BINGKAI FOTO | C4: 2 | D4: PCE - Piece | E4: 3 | F4: CDD Box 1 | G4: Kardus perlengkapan dapur | H4: 10 | I4: 60 | J4: 50 | K4: 45 | L4: 18 | M4: =H4*L4 -> 180 | N4: =I4*J4*K4/1000000 -> 0.135 | O4: =H4*N4 -> 1.35
A5: 4 | B5: LEMARI | C5: 1 | D5: PCE - Piece | E5: 4 | F5: CDD Box 1 | G5: Lemari pakaian | H5: 2 | I5: 200 | J5: 60 | K5: 20 | L5: 40 | M5: =H5*L5 -> 80 | N5: =I5*J5*K5/1000000 -> 0.24 | O5: =H5*N5 -> 0.48
A6: 5 | B6: MEJA KERJA | C6: 1 | D6: PCE - Piece | E6: 5 | F6: CDD Box 1 | G6: Kasur queen | H6: 1 | I6: 200 | J6: 160 | K6: 30 | L6: 45 | M6: =H6*L6 -> 45 | N6: =I6*J6*K6/1000000 -> 0.96 | O6: =H6*N6 -> 0.96
A7: 6 | B7: MESIN JAHIT | C7: 1 | D7: PCE - Piece | E7: 6 | F7: CDD Box 1 | G7: Bed base queen | H7: 1 | I7: 200 | J7: 160 | K7: 25 | L7: 55 | M7: =H7*L7 -> 55 | N7: =I7*J7*K7/1000000 -> 0.8 | O7: =H7*N7 -> 0.8
A8: 7 | B8: KULKAS | C8: 1 | D8: PCE - Piece | E8: 7 | F8: CDD Box 1 | G8: Sofa 3 seater | H8: 1 | I8: 200 | J8: 85 | K8: 80 | L8: 75 | M8: =H8*L8 -> 75 | N8: =I8*J8*K8/1000000 -> 1.36 | O8: =H8*N8 -> 1.36
A9: 8 | B9: DISPENSER | C9: 2 | D9: PCE - Piece | E9: 8 | F9: CDD Box 1 | G9: Sofa 1 seater | H9: 2 | I9: 90 | J9: 85 | K9: 80 | L9: 35 | M9: =H9*L9 -> 70 | N9: =I9*J9*K9/1000000 -> 0.612 | O9: =H9*N9 -> 1.224
A10: 9 | B10: KARPET | C10: 2 | D10: PCE - Piece | E10: 9 | F10: CDD Box 1 | G10: Meja makan | H10: 1 | I10: 160 | J10: 90 | K10: 20 | L10: 45 | M10: =H10*L10 -> 45 | N10: =I10*J10*K10/1000000 -> 0.288 | O10: =H10*N10 -> 0.288
A11: 10 | B11: CPU | C11: 1 | D11: PCE - Piece | E11: 10 | F11: CDD Box 1 | G11: Kursi makan | H11: 2 | I11: 60 | J11: 60 | K11: 100 | L11: 30 | M11: =H11*L11 -> 60 | N11: =I11*J11*K11/1000000 -> 0.36 | O11: =H11*N11 -> 0.72
A12: 11 | B12: JEMURAN | C12: 1 | D12: PCE - Piece | E12: 11 | F12: CDD Box 1 | G12: Kulkas 2 pintu | H12: 1 | I12: 70 | J12: 70 | K12: 180 | L12: 75 | M12: =H12*L12 -> 75 | N12: =I12*J12*K12/1000000 -> 0.882 | O12: =H12*N12 -> 0.882
A13: 12 | B13: TV | C13: 1 | D13: PCE - Piece | E13: 12 | F13: CDD Box 1 | G13: Mesin cuci | H13: 1 | I13: 65 | J13: 65 | K13: 95 | L13: 55 | M13: =H13*L13 -> 55 | N13: =I13*J13*K13/1000000 -> 0.401375 | O13: =H13*N13 -> 0.401375
... A37: 36 | B37: PAKAIAN | C37: 20 | D37: PCE - Piece | E37: 36 | F37: CDD Box 2 | G37: Standing hanger/rak pakaian | H37: 2 | I37: 120 | J37: 50 | K37: 160 | L37: 20 | M37: =H37*L37 -> 40 | N37: =I37*J37*K37/1000000 -> 0.96 | O37: =H37*N37 -> 1.92

Sheet rekap CBA 1
B1: PT POS INDONESIA (PERSERO)
B2: KCU BATAM 29400
B3: COST AND BENEFIT ANALYSIS ( CBA )
B4: KCU BATAM 29400
B6: 1. NAMA PELANGGAN | D6: BANK SYARIAH NASIONAL BATAM
B7: 2. JENIS KIRIMAN (KOMODITI) | D7: Barang Pindah
B8: 3. TUJUAN KIRIMAN | D8: Padang
B9: 4. JENIS LAYANAN | D9: FREIGHT FORWARDING
B10: 5. ALAT TRANSPORTASI | D10: Darat
B11: 6. NILAI PROYEK | D11: =SUM(D12:D15) -> 33000000
C12: PENDAPATAN KARGO | D12: ='CBA2'!F36 -> 33000000 | E12: cba online
C13: PPN ( 1,1%) | D13: ='CBA2'!G36 -> 0
C14: Pendapatan Packing | D14: =+'CBA2'!J36 -> 0
C15: PPn (11%) | D15: =+'CBA2'!I36 -> 0
B16: 7. NILAI BARANG
B17: 8. VOLUME PROYEK | D17: ='CBA2'!C36 -> 2587 | E17: Kg
B18: 9. PERIODE PELAKSANAAN | D18: 16 September S/D 31 September 2026
B19: 10. TERMIN WAKTU PEMBAYARAN | D19: Per SPK 30 Hari
B21: NO | C21: NO REKENING | D21: KELOMPOK BIAYA | E21: BIAYA TAK LANGSUNG - REGULER | F21: BIAYA LANGSUNG | G21: JUMLAH BIAYA
B22: 1 | C22: 51.01.01.02.01 | D22: Beban Tenaga Kontrak | G22: =E22+F22 -> 0
D23: Jumlah Beban Pegawai | E23: =SUM(E22) -> 0 | F23: =SUM(F22) -> 0 | G23: =SUM(G22) -> 0
C24: Beban Operasi | G24: =E24+F24 -> 0
B25: 2 | C25: 51.02.01.03.02 | D25: Peningkatan Mutu | G25: =E25+F25 -> 0
B26: 3 | C26: 51.02.02.01.01 | D26: Ongkos Bongkar Muat Kantungpos | G26: =E26+F26 -> 0
B27: 4 | C27: 51.02.02.01.02 | D27: Gudang Dan Pengepakan | G27: =E27+F27 -> 0
B28: 5 | C28: 51.02.03.01.01 | D28: Pesawat Udara Dalam negeri | G28: =E28+F28 -> 0
B29: 6 | C29: 51.02.03.01.02 | D29: Kapal Laut/Angkutan Sungai/Danau Dalam Negeri | G29: =E29+F29 -> 0
B30: 7 | C30: 51.02.05.00.02 | D30: Sewa Kendaraan Roda 4 dan 6 | F30: ='CBA2'!S36 -> 28600000 | G30: =E30+F30 -> 28600000
B31: 8 | C31: 51.02.05.00.04 | D31: Bahan Bakar Minyak dan Pelumas | G31: =E31+F31 -> 0
B32: 9 | C32: 51.02.08.00.01 | D32: Pemasaran Surat Pos dan Paket Pos | F32: ='RBL 2'!F36 -> 0 | G32: =E32+F32 -> 0
B33: 10 | C33: 51.02.08.00.02 | D33: Pemasaran Logistik | G33: =E33+F33 -> 0
C34: Jumlah Beban Operasi | E34: =SUM(E25:E33) -> 0 | F34: =SUM(F25:F33) -> 28600000 | G34: =SUM(G25:G33) -> 28600000
C35: Beban Administrasi | G35: =E35+F35 -> 0
B36: 11 | C36: 51.03.01.00.01 | D36: Alat Tulis Menulis | F36: 2200000 | G36: =E36+F36 -> 2200000
B37: 12 | C37: 51.03.01.00.03 | D37: Pemakaian Fotocopy | F37: ='RBL 2'!F24 -> 0 | G37: =E37+F37 -> 0
C38: Jumlah Beban Administrasi | E38: =SUM(E36:E37) -> 0 | F38: =SUM(F36:F37) -> 2200000 | G38: =SUM(G36:G37) -> 2200000
C39: Beban Umum | G39: =E39+F39 -> 0
B40: 13 | C40: 51.04.03.00.01 | D40: ='RBL 2'!E26 -> Perjalanan Dinas Dalam Negeri | F40: ='RBL 2'!F31 -> 0 | G40: =E40+F40 -> 0
B41: 14 | C41: 51.04.04.00.02 | D41: Penyelenggaraan Rapat | G41: =E41+F41 -> 0
C42: Jumlah Beban Umum | E42: =SUM(E40:E41) -> 0 | F42: =SUM(F40:F41) -> 0 | G42: =SUM(G40:G41) -> 0
...

Sheet RBL
B1: PT POS INDONESIA
B2: KCU BATAM 29400
B3: RINCIAN BIAYA LANGSUNG
B4: ='rekap CBA 1'!D6 -> BANK SYARIAH NASIONAL BATAM
B5: ID PROYEK : CB2940026022 KIRIMAN BARNAG PINDAH TUJUAN PURWOKERTO
B6: No | C6: Korek | D6: Kelompok Beban | E6: Besar Uang | F6: Keterangan
B8: I | C8: 5102 | D8: Beban Operasi
C9: 5102050004 | D9: Bahan Bakar Minyak dan Pelumas | E9: ='CBA2'!L36 -> 0
B10: 1 | C10: 5102050002 | D10: Sewa Kendaraan Roda 4 dan 6 | E10: ='CBA2'!S36 -> 28600000
B11: 2 | C11: 5102020101 | D11: Ongkos Bongkar Muat Kantungpos
B12: 3 | C12: 5102020102 | D12: Biaya Gudang & Pengepakan
B13: 4 | C13: 5102080001 | D13: Pemasaran Surat Pos dan Paket Pos | E13: ='RBL 2'!F36 -> 0
D16: SUB JUMLAH | E16: =SUM(E9:E13) -> 28600000
B17: II | C17: 5103 | D17: BEBAN ADM
B18: 1 | C18: 5103010001 | D18: Alat Tulis Menulis
B19: 2 | C19: 5103010002 | D19: Perlengkapan Kantor
B20: 3 | C20: 5103010003 | D20: Pemakaian Fotocopy | E20: ='RBL 2'!F24 -> 0
D21: SUB JUMLAH | E21: =SUM(E18:E20) -> 0
B23: III | C23: 5104 | D23: BEBAN UMUM
B24: 1 | C24: 5104030001 | D24: Perjalanan Dinas Dalam Negeri | E24: ='RBL 2'!F31 -> 0
B25: 2 | C25: 5104010002 | D25: Pemakaian Telepon/Telegram/Fax
B26: 3 | C26: 5104040002 | D26: Penyelenggaraan Rapat
B27: SUB JUMLAH | E27: =SUM(E24:E26) -> 0
D28: TOTAL BIAYA | E28: =E16+E21+E27 -> 28600000
B29: JUMLAH BERAT | E29: ='CBA2'!C36 -> 2587
B30: BIAYA PER KG | E30: =E28/E29 -> 11055.276
F33: ='rekap CBA 1'!G59 -> Batam, 17 September 2026
C34: Mengetahuai : | E34: Diperiksa Oleh : | G34: Dibuat Oleh
C35: EGM KCU BATAM | E35: Manajer Penjualan | G35: AM Penjualan
C39: Khresna Adi Nugraha | E39: Ikhsan Radiansyah | G39: Riani Nindiyanti
C40: Nippos : 986393010 | E40: Nippos : 995480412 | G40: Nippos : 987413820
C42: Ditetapkan Oleh | E42: Mengetahui | G42: Mengetahui
C43: EVP Regional I | E43: Deputi EVP | G43: Deputi OVP
C47: Raden Bagus Muhammad Yusuf
C48: Nippos : 973343140

Sheet RBL 2
A1: PT POS INDONESIA (PERSERO) | F1: Lampiran 3
A2: KCU BATAM 29400
A3: RAB BIAYA ADMINISTRASI DAN UMUM
A4: ='rekap CBA 1'!D7 -> Barang Pindah
A5: ='rekap CBA 1'!D18 -> 16 September S/D 31 September 2026
A7: NO | B7: URAIAN | C7: JUMLAH UNIT | D7: SATUAN | E7: HARGA PERUNIT | F7: JUMLAH
E8: (Rp) | F8: (Rp)
A9: A. | B9: BIAYA ADMINISTRASI | C9: 51 03 01 0001 | E9: Alat Tulis Kantor (ATK)
D10: Roll | F10: =+C10*E10 -> 0
D11: Roll | F11: =+C11*E11 -> 0
D12: Roll | F12: =+C12*E12 -> 0
D13: Pcs | F13: =+C13*E13 -> 0
F14: =+C14*E14 -> 0
F15: =+C15*E15 -> 0
F16: =+C16*E16 -> 0
F17: =SUM(F10:F16) -> 0
A18: B | B18: BIAYA ADMINISTRASI | C18: 51 03 01 0003 | E18: Pemakaian Fotocopy
B19: Pemakaian Fotocopy | D19: lbr | F19: =+C19*E19 -> 0
B20: SKEP, PKS, SE | D20: lbr | F20: =+C20*E20 -> 0
B21: Penjilidan dokumen Tender | D21: buku | F21: =+C21*E21 -> 0
B22: Materai | D22: lbr | F22: =+C22*E22 -> 0
B23: Penjilidan dokumen Pengadaan | D23: buku | F23: =+C23*E23 -> 0
F24: =SUM(F19:F23) -> 0
B25: JUMLAH BIAYA ADMINISTRASI | F25: =F17+F24 -> 0
A26: C | B26: BIAYA UMUM | C26: 51 04 03 0001 | E26: Perjalanan Dinas Dalam Negeri
B27: Perjalanan Dinas Dalam Negeri
B28: a. Tiket Pesawat | F28: =+C28*E28 -> 0
B29: b. Hotel | F29: =+C29*E29 -> 0
B30: c. Sewa mobil setempat (4 hari) | F30: =+C30*E30 -> 0
F31: =SUM(F28:F30) -> 0
A32: D | B32: PEMASARAN SURAT POS DAN PAKET POS | C32: 51 02 08 0001 | E32: Pemasaran Surat Pos dan Paket Pos
B33: Pemasaran Surat Pos dan Pekat Pos
B34: a. Pembahasan Project Tali Tross | F34: =+C34*E34 -> 0
B35: b. Maintenance dan evaluasi Project | F35: =+C35*E35 -> 0
F36: =SUM(F34:F35) -> 0
B37: JUMLAH BIAYA UMUM
B39: JUMLAH BIAYA ADMINISTRASI DAN UMUM | F39: =F36+F31+F25+F17 -> 0
F41: ='rekap CBA 1'!G59 -> Batam, 17 September 2026
B42: Mengetahuai : | D42: Diperiksa Oleh : | F42: Dibuat Oleh
B43: EGM KCU KCU BATAM | D43: Manajer Penjualan | F43: AM Penjualan
...

Sheet SOW SHADOW
B2: SCOPE OF WORK
B3: ID Dan Judul Proyek | C3: : | D3: CB2940026023 | Pengiriman Barang Pindah Tujuan Tangerang
B5: 1.1 Client and Project Information
B6: Nama Mitra : | F6: Project Location
B7: TEMPO | F7: BATAM - Tangerang
B8: Nama PIC : | F8: REGIONAL/KCU/KC Penanggung Jawab :
B9: Lukmanur Hakim | F9: BATAM
B10: Alamat Mitra : | F10: Nama PIC / Jabatan / CP :
B11: Jl. Cemara Papua No. 21, Bukit Indah Sukajadi, Batam | F11: RIKY JULIADI/AM PENJUALAN/
B12: No Telp dan No Hp : | F12: GAMBAR POLA OPERASI
B13: 0811-126-263
B14: E-Mail :
B15: mail@thetempogroup.com
B16: Penjelasan Pola Operasi :
B17: Permintaan Customer : Sewa 2 Mobil Angkutan Operasional pengiriman barang pindah Bapak Lukmanur ini dijalankan dengan skema Door-to-Door menggunakan moda transportasi darat dan penyeberangan (RoRo) dengan sistem multi-drop. Tahap awal dimulai dengan penjemputan (pickup) seluruh muatan di Rumah Bapak Lukmanur di Sukajadi Batam. Barang kemudian dimobilisasi menuju Kantor Pos Batam untuk melalui proses standarisasi keamanan, meliputi pembuatan packing bubble wrap dan wrapping platic, wrapping menyeluruh, serta validasi final terhadap Packing List untuk memastikan kesesuaian data. Fase krusial selanjutnya adalah penyelesaian administrasi kepabeanan (PPFTZ01) sesuai regulasi Free Trade Zone. Proses dimulai dengan input data manifest melalui sistem Ion Beta, yang dilanjutkan dengan sesi wawancara pemilik barang di Kantor Bea Cukai Batu Ampar. Setelah itu, dilakukan pemeriksaan fisik barang secara mendetail di Tempat Penimbunan Sementara (TPS) Pos Batam. Apabila hasil pemeriksaan fisik dan dokumen dinyatakan sesuai dalam Berita Acara, Bea Cukai akan menerbitkan Surat Persetujuan Pengeluaran Barang (SPPB). Sebagai langkah pengamanan terakhir di Batam, truk akan disegel (seal) dan ditempel stiker pengaman resmi oleh petugas Bea Cukai sebelum meninggalkan area TPS. Pada tahap mobilisasi, armada bergerak menuju Pelabuhan Punggur. Di lokasi ini, segel dan stiker pengaman akan dilepas oleh petugas Bea Cukai setempat sebagai prosedur standar sebelum truk menyeberang menuju Pelabuhan Tanjung Buton. Perjalanan darat kemudian dilanjutkan menuju Tangerang. setibanya di Banyumas, kiriman dilakukan pengantaran dan bongkar kiriman di rumah Bapak Lukmanur Jl. Merak Raya No 173 RT 02 RW 012 Kel. Cibodasari Kecamatan Cibodas, Perumnas 1, Kota Tangerang. 15138
B18: 1.2 Project Detail / Detail Proyek
B19: Origine (Asal Kiriman) | C19: : | D19: Nama Origin | F19: Jumlah Origin
B20: Batam | C20: : | D20: Jl. Cemara Papua No. 21, Bukit Indah Sukajadi, Batam | H20: Single Pick Up
B21: Destinasi (Tujuan Kiriman) | C21: : | D21: Nama Destinasi | F21: Jumlah Destinasi | H21: Single Drop
B22: Banyumas | C22: : | D22: Jl. Sunan Bonang No.25, Desa Tambaksari Kidul RT 1/RW 4, Kembaran, Banyumas, Jawa Tengah 53182 | F22: 1 | H22: Single Drop
B23: Jenis Cargo (General/Special/Dangerious Good) dan Nama Cargo : | C23: : | D23: General Cargo : Cargo Darat dan Laut
B24: Bentuk Kiriman | C24: : | D24: Kiriman Barang Pindahan
B25: Tujuan Proyek | C25: : | D25: Barang Pindahan
B26: Frekuensi Pelaksaan | C26: : | D26: Sekali dalam Masa Proyek
B27: Berat Kiriman (per koli) | C27: : | D27: 2587 Kg | F27: total berat | G27: = | H27: 2587 Kg
B28: Dimensi Per koli (cm) | C28: : | D28: P60 X L50 X T50 cm
B29: Jumlah Koli | C29: : | D29: 122 Koli
B30: Estimasi trip | C30: : | D30: 14 Hari
B31: Pola Operasi | C31: : | D31: Door to Door
B32: Jenis Layanan (FTL/LTL) | C32: : | D32: Door to Door
B33: Jenis Kendaraan | C33: : | D33: CDD
B34: 1.3 Vendor Selection Process/Proses Pemilihan Vendor
B35: Syarat mitra penyedia jasa | C35: : | D35: Kendaraan vendor harus sesuai jenis kargo ; Kendaraan vendor mampu mengakomodir dan mendistribusi kiriman dengan aman; Tidak memungkinkan diangkut bersama kiriman reguler PT Pos Indonesia karena kuantitas banyak; kiriman dilakukan secara bersamaan dan membutuhkan penanganan khusus
C36: : | D36: 1. Memiliki dokumen legalitas sebagai berikut: a) Akte pendirian perusahaan beserta akta perubahannya yang telah terdaftar di Departemen terkait; b) SIUP; c) SITU/Keterangan Domisili; d) Tanda Daftar Perusahaan (TDP); e) SPKP; f) Nomor Induk Berusaha (NIB); g) NPWP
D37: 2. Memiliki armada sesuai dengan kebutuhan customer dan jaringan service sesuai kebutuhan customer
D38: 3. Memiliki kecakapan, keahlian (core competence), pengalaman, kemampuan teknis, dan manajerial serta kewenangan dalam melakukan perjanjian
D39: 4. Memiliki sumber daya manusia, modal, dan infrastruktur yang diperlukan dalam bisnis sebagai mitra
D40: 5. Tidak sedang dalam pengawasan pengadilan, tidak dinyatakan dalam keadaan pailit oleh pengadilan, kegiatan usahanya sedang tidak dihentikan dan/atau tidak sedang menjalani sanksi pidana yang dinyatakan secara tertulis
D41: 6. Mampu bekerja sesuai dengan SLA yang disepakati
B42: Vendor Terpilih | C42: : | D42: CV EMY RIZKY JAYA
...
